<?xml version="1.0"?>
<robot xmlns:xacro="http://www.ros.org/wiki/xacro">

    <xacro:macro name="chaster_wheel" params="name parent xyz rpy  *origin ">
        <link name="${name}_link">

            <visual>
                <origin rpy="${rpy}" xyz="${xyz}" />
                <geometry>
                    <mesh filename="package://service_description/meshes/sarhos_tabla/sarhos_teker.STL" scale="0.001 0.001 0.001" />
                </geometry>
                <material name="green">
                    <color rgba="0 1 0 1" />
                </material>
            </visual>
            <collision>
                <origin rpy="${rpy}" xyz="${xyz}" />
                <geometry>
                    <cylinder length="0.01" radius="0.015" />
                </geometry>
            </collision>
            <inertial>
                <origin rpy="${rpy}" xyz="${xyz}" />
                <mass value="0.1" />
                <inertia ixx="6.458333333333333e-06" ixy="0" ixz="0" iyy="6.458333333333333e-06" iyz="0" izz="1.1249999999999999e-05">
                 <!--  kg for small/big battery pack -->
                <!-- servicebot's inertia tensor is approximated by a cylinder with homogeneous mass distribution
             More details: http://en.wikipedia.org/wiki/List_of_moment_of_inertia_tensors
             m = 2.4 kg; h = 0.09 m; r = 0.175 m
             ixx = 1/12 * m * (3 * r^2 + h^2)
             iyy = 1/12 * m * (3 * r^2 + h^2)
             izz = 1/2 * m * r^2
          -->
                </inertia>
            </inertial>
        </link>

    

        <joint name="${name}_joint" type="continuous">
            <parent link="${parent}" />
            <child link="${name}_link" />
            <xacro:insert_block name="origin" />
            <axis xyz="0 1 0" />
            <dynamics damping="0.1" friction="0.1" />
        </joint>
    </xacro:macro>
</robot>