<?xml version="1.0" encoding="UTF-8"?>
<robot xmlns:xacro="http://www.ros.org/wiki/xacro">
    <xacro:macro name="wheel" params="name parent xyz rpy *origin">
        <joint name="${name}_joint" type="continuous">
            <xacro:insert_block name="origin" />
            <parent link="${parent}" />
            <child link="${name}" />
            <axis xyz="0 1 0" />
        </joint>
        <link name="${name}">
            <visual>
                <geometry>
                    <mesh filename="package://service_description/meshes/servis/reduktorteker.STL" scale="0.001 0.001 0.001" />
                </geometry>
                <!-- <origin xyz="-0.155 -0.079 ${0.0725 + 0.01}" rpy="0 1.5779 0" /> -->
                <origin xyz="${xyz}" rpy="${rpy}" />
            </visual>
            <collision>
                <geometry>
                    <!-- <cylinder length="0.142" radius="0.006" /> -->
                    <mesh filename="package://service_description/meshes/servis/reduktorteker.STL" scale="0.001 0.001 0.001" />
                </geometry>
                <!-- <origin xyz="-0.155 -0.079 ${0.0725 + 0.01}" rpy="0 1.57079 0" /> -->
                <origin xyz="${xyz}" rpy="${rpy}" />
            </collision>
        </link>
    </xacro:macro>
</robot>