<?xml version="1.0" encoding="UTF-8"?>
<robot xmlns:xacro="http://www.ros.org/wiki/xacro" name="servicebot">
    <xacro:macro name="wheel" params="name parent *origin">
        <joint name="${name}_joint" type="continuous">
            <xacro:insert_block name="origin" />
            <parent link="${parent}" />
            <child link="${name}" />
            <axis xyz="0 1 0" />
        </joint>
        <link name="${name}">
            <visual>
                <origin xyz="0.08 -0.15 0.08" rpy="0 1.57 1.57" />
                <geometry>
                    <mesh filename="package://service_description_clean/meshes/servis/wheel.STL" scale="0.001 0.001 0.001" />
                </geometry>
            </visual>
        </link>
    </xacro:macro>
    <xacro:macro name="camera" params="name parent *origin">
        <joint name="${name}_joint" type="fixed">
            <xacro:insert_block name="origin" />
            <parent link="${parent}" />
            <child link="${name}" />
        </joint>
        <link name="${name}">
            <visual>
                <origin xyz="0.01 0 0" rpy="1.57 0 1.57" />
                <geometry>
                    <mesh filename="package://service_description_clean/meshes/sensors/d435.dae" />
                </geometry>
            </visual>
        </link>
    </xacro:macro>
</robot>